<?xml version="1.0" ?>
<!-- =================================================================================== -->
<!-- |    This document was autogenerated by xacro from goblet.xacro                   | -->
<!-- |    EDITING THIS FILE BY HAND IS NOT RECOMMENDED                                 | -->
<!-- =================================================================================== -->
<robot name="robot_with_goblet">
  <!-- links: main serial chain -->
  <link name="base_link">
    <visual>
      <origin rpy="0 0 0" xyz="0 0 0"/>
      <geometry>
        <mesh filename="file:/home/audrius/opw/goblets/rx160/base_link.stl"/>
      </geometry>
      <material name="robot">
        <color rgba="0.51 0.58 0.75 1"/>
      </material>
    </visual>
    <collision>
      <origin rpy="0 0 0" xyz="0 0 0"/>
      <geometry>
        <mesh filename="file:/home/audrius/opw/goblets/rx160/base_link.stl"/>
      </geometry>
    </collision>
    <inertial>
      <mass value="23.085357"/>
      <origin rpy="0.0 0.0 0.0" xyz="0.007579 0.000017 0.180670"/>
      <inertia ixx="0.343576" ixy="-0.000062" ixz="-0.002079" iyy="0.336217" iyz="-0.000014" izz="0.334050"/>
    </inertial>
  </link>
  <link name="link_1">
    <visual>
      <origin rpy="0 0 0" xyz="0 0 0"/>
      <geometry>
        <mesh filename="file:/home/audrius/opw/goblets/rx160/link_1.stl"/>
      </geometry>
      <material name="robot"/>
    </visual>
    <collision>
      <origin rpy="0 0 0" xyz="0 0 0"/>
      <geometry>
        <mesh filename="file:/home/audrius/opw/goblets/rx160/link_1.stl"/>
      </geometry>
    </collision>
    <inertial>
      <mass value="45.357763"/>
      <origin rpy="0.0 0.0 0.0" xyz="0.085479 -0.002547 -0.040488"/>
      <inertia ixx="0.839141" ixy="0.022637" ixz="0.162457" iyy="1.030146" iyz="0.027416" izz="1.064698"/>
    </inertial>
  </link>
  <link name="link_2">
    <visual>
      <origin rpy="0 0 0" xyz="0 0 0"/>
      <geometry>
        <mesh filename="file:/home/audrius/opw/goblets/rx160/link_2.stl"/>
      </geometry>
      <material name="robot"/>
    </visual>
    <collision>
      <origin rpy="0 0 0" xyz="0 0 0"/>
      <geometry>
        <mesh filename="file:/home/audrius/opw/goblets/rx160/link_2.stl"/>
      </geometry>
    </collision>
    <inertial>
      <mass value="51.266495"/>
      <origin rpy="0.0 0.0 0.0" xyz="-0.000002 0.264164 0.347704"/>
      <inertia ixx="5.272800" ixy="0.000010" ixz="0.000017" iyy="5.536809" iyz="-0.008261" izz="0.486191"/>
    </inertial>
  </link>
  <link name="link_3">
    <visual>
      <origin rpy="0 0 0" xyz="0 0 0"/>
      <geometry>
        <mesh filename="file:/home/audrius/opw/goblets/rx160/link_3.stl"/>
      </geometry>
      <material name="robot"/>
    </visual>
    <collision>
      <origin rpy="0 0 0" xyz="0 0 0"/>
      <geometry>
        <mesh filename="file:/home/audrius/opw/goblets/rx160/link_3.stl"/>
      </geometry>
    </collision>
    <inertial>
      <mass value="19.754401"/>
      <origin rpy="0.0 0.0 0.0" xyz="-0.000255 0.016478 -0.003819"/>
      <inertia ixx="0.249388" ixy="-0.004901" ixz="0.004825" iyy="0.211780" iyz="0.000574" izz="0.238488"/>
    </inertial>
  </link>
  <link name="link_4">
    <visual>
      <origin rpy="0 0 0" xyz="0 0 0"/>
      <geometry>
        <mesh filename="file:/home/audrius/opw/goblets/rx160/link_4.stl"/>
      </geometry>
      <material name="robot"/>
    </visual>
    <collision>
      <origin rpy="0 0 0" xyz="0 0 0"/>
      <geometry>
        <mesh filename="file:/home/audrius/opw/goblets/rx160/link_4.stl"/>
      </geometry>
    </collision>
    <inertial>
      <mass value="15.287896"/>
      <origin rpy="0.0 0.0 0.0" xyz="-0.015515 0.000164 0.340348"/>
      <inertia ixx="0.331593" ixy="0.000055" ixz="-0.010688" iyy="0.320895" iyz="0.000058" izz="0.086557"/>
    </inertial>
  </link>
  <link name="link_5">
    <visual>
      <origin rpy="0 0 0" xyz="0 0 0"/>
      <geometry>
        <mesh filename="file:/home/audrius/opw/goblets/rx160/link_5.stl"/>
      </geometry>
      <material name="robot"/>
    </visual>
    <collision>
      <origin rpy="0 0 0" xyz="0 0 0"/>
      <geometry>
        <mesh filename="file:/home/audrius/opw/goblets/rx160/link_5.stl"/>
      </geometry>
    </collision>
    <inertial>
      <mass value="0.548088"/>
      <origin rpy="0.0 0.0 0.0" xyz="0.000000 -0.000347 0.023671"/>
      <inertia ixx="0.000876" ixy="0.000000" ixz="0.000000" iyy="0.000889" iyz="0.000005" izz="0.000412"/>
    </inertial>
  </link>
  <link name="link_6">
    <visual>
      <origin rpy="0 0 0" xyz="0 0 0"/>
      <geometry>
        <mesh filename="file:/home/audrius/opw/goblets/rx160/link_6.stl"/>
      </geometry>
      <material name="robot"/>
    </visual>
    <collision>
      <origin rpy="0 0 0" xyz="0 0 0"/>
      <geometry>
        <mesh filename="file:/home/audrius/opw/goblets/rx160/link_6.stl"/>
      </geometry>
    </collision>
    <inertial>
      <mass value="0.038484"/>
      <origin rpy="0.0 0.0 0.0" xyz="-0.000245 0.000000 -0.007626"/>
      <inertia ixx="0.000011" ixy="0.000000" ixz="0.000000" iyy="0.000011" iyz="0.000000" izz="0.000021"/>
    </inertial>
  </link>
  <!-- joints: main serial chain -->
  <joint name="joint_1" type="revolute">
    <origin rpy="0 0 0" xyz="0 0 0.55"/>
    <parent link="base_link"/>
    <child link="link_1"/>
    <axis xyz="0 0 1"/>
    <limit effort="692.0" lower="-2.792526803190927" upper="2.792526803190927" velocity="3.490658503988659"/>
    <dynamics damping="0.0" friction="0.0"/>
  </joint>
  <joint name="joint_2" type="revolute">
    <origin rpy="0 0 0" xyz="0.15 0 0"/>
    <parent link="link_1"/>
    <child link="link_2"/>
    <axis xyz="0 1 0"/>
    <limit effort="574.0" lower="-2.399827721492203" upper="2.399827721492203" velocity="3.490658503988659"/>
    <dynamics damping="0.0" friction="0.0"/>
  </joint>
  <joint name="joint_3" type="revolute">
    <origin rpy="0 0 0" xyz="0 0 0.825"/>
    <parent link="link_2"/>
    <child link="link_3"/>
    <axis xyz="0 1 0"/>
    <limit effort="242.0" lower="-2.6179938779914944" upper="2.6179938779914944" velocity="4.4505895925855405"/>
    <dynamics damping="0.0" friction="0.0"/>
  </joint>
  <joint name="joint_4" type="revolute">
    <origin rpy="0 0 0" xyz="0 0 0"/>
    <parent link="link_3"/>
    <child link="link_4"/>
    <axis xyz="0 0 1"/>
    <limit effort="58.0" lower="-4.71238898038469" upper="4.71238898038469" velocity="5.497787143782138"/>
    <dynamics damping="0.0" friction="0.0"/>
  </joint>
  <joint name="joint_5" type="revolute">
    <origin rpy="0 0 0" xyz="0 0 0.625"/>
    <parent link="link_4"/>
    <child link="link_5"/>
    <axis xyz="0 1 0"/>
    <!-- from Staubli instruction manual:
      (1) effort limit = 58 Nm if axis 6 torque = 0 Nm
      (2) effort limit = 29 Nm for maximum torque on axis 6 -->
    <limit effort="29.0" lower="-1.8325957145940461" upper="2.0943951023931953" velocity="6.283185307179586"/>
    <dynamics damping="0.0" friction="0.0"/>
  </joint>
  <joint name="joint_6" type="revolute">
    <origin rpy="0 0 0" xyz="0 0 0.11"/>
    <parent link="link_5"/>
    <child link="link_6"/>
    <axis xyz="0 0 1"/>
    <limit effort="29.0" lower="-4.71238898038469" upper="4.71238898038469" velocity="15.184364492350667"/>
    <dynamics damping="0.0" friction="0.0"/>
  </joint>
  <!-- ROS-Industrial 'base' frame: base_link to Staubli World Coordinates transform -->
  <link name="base"/>
  <joint name="base_link-base" type="fixed">
    <origin rpy="0 0 0" xyz="0 0 0.550"/>
    <parent link="base_link"/>
    <child link="base"/>
  </joint>
  <!-- ROS-Industrial 'flange' frame: attachment point for EEF models -->
  <link name="flange"/>
  <joint name="joint_6-flange" type="fixed">
    <origin rpy="0 -1.5707963267948966 0" xyz="0 0 0"/>
    <parent link="link_6"/>
    <child link="flange"/>
  </joint>
  <!-- ROS-Industrial 'tool0' frame: all-zeros tool frame -->
  <link name="tool0"/>
  <joint name="flange-tool0" type="fixed">
    <origin rpy="0 1.5707963267948966 0" xyz="0 0 0"/>
    <parent link="flange"/>
    <child link="tool0"/>
  </joint>
  <link name="world"/>
  <!-- Goblet Link -->
  <link name="goblet_base">
    <visual>
      <geometry>
        <mesh filename="file:/home/audrius/opw/goblets/goblet.stl"/>
      </geometry>
      <material name="goblet">
        <color rgba="1 0.5 0.5 0.3"/>
      </material>
    </visual>
    <visual>
      <origin rpy="0 0 0" xyz="0 0 1.0"/>
      <geometry>
        <sphere radius="0.01"/>
      </geometry>
      <material name="goblet"/>
    </visual>
  </link>
  <link name="stick">
    <visual>
      <geometry>
        <mesh filename="file:/home/audrius/opw/goblets/stick.stl"/>
      </geometry>
      <material name="tool">
        <color rgba="1 1 1 1.0"/>
      </material>
    </visual>
  </link>
  <!-- Attach Goblet -->
  <joint name="attach_goblet" type="fixed">
    <parent link="world"/>
    <child link="goblet_base"/>
    <origin rpy="0 0 0" xyz="0 0 0"/>
  </joint>
  <!-- Attach robot at the center of the world upside down at height 1.7 -->
  <joint name="robot_stand" type="fixed">
    <parent link="world"/>
    <child link="base_link"/>
    <origin rpy="0 3.1415 0" xyz="0 0 1.7"/>
  </joint>
  <!-- Attach tool -->
  <joint name="tool" type="fixed">
    <parent link="tool0"/>
    <child link="stick"/>
    <origin rpy="0 0 0" xyz="0 0 0"/>
  </joint>
  <virtual_joint child_link="base_link" name="world_joint" parent_frame="world" type="fixed"/>
</robot>
